<sdf version='1.7'>
  <world name='default'>
    <light name='sun' type='directional'>
      <cast_shadows>1</cast_shadows>
      <pose>0 0 10 0 -0 0</pose>
      <diffuse>0.8 0.8 0.8 1</diffuse>
      <specular>0.2 0.2 0.2 1</specular>
      <attenuation>
        <range>1000</range>
        <constant>0.9</constant>
        <linear>0.01</linear>
        <quadratic>0.001</quadratic>
      </attenuation>
      <direction>-0.5 0.1 -0.9</direction>
      <spot>
        <inner_angle>0</inner_angle>
        <outer_angle>0</outer_angle>
        <falloff>0</falloff>
      </spot>
    </light>
    <model name='ground_plane'>
      <static>1</static>
      <link name='link'>
        <collision name='collision'>
          <geometry>
            <plane>
              <normal>0 0 1</normal>
              <size>100 100</size>
            </plane>
          </geometry>
          <surface>
            <friction>
              <ode>
                <mu>100</mu>
                <mu2>50</mu2>
              </ode>
              <torsional>
                <ode/>
              </torsional>
            </friction>
            <contact>
              <ode/>
            </contact>
            <bounce/>
          </surface>
          <max_contacts>10</max_contacts>
        </collision>
        <visual name='visual'>
          <cast_shadows>0</cast_shadows>
          <geometry>
            <plane>
              <normal>0 0 1</normal>
              <size>100 100</size>
            </plane>
          </geometry>
          <material>
            <script>
              <uri>file://media/materials/scripts/gazebo.material</uri>
              <name>Gazebo/Grey</name>
            </script>
          </material>
        </visual>
        <self_collide>0</self_collide>
        <enable_wind>0</enable_wind>
        <kinematic>0</kinematic>
      </link>
    </model>
    <gravity>0 0 -9.8</gravity>
    <magnetic_field>6e-06 2.3e-05 -4.2e-05</magnetic_field>
    <atmosphere type='adiabatic'/>
    <physics type='ode'>
      <max_step_size>0.001</max_step_size>
      <real_time_factor>1</real_time_factor>
      <real_time_update_rate>1000</real_time_update_rate>
    </physics>
    <scene>
      <ambient>0.4 0.4 0.4 1</ambient>
      <background>0.7 0.7 0.7 1</background>
      <shadows>1</shadows>
    </scene>
    <audio>
      <device>default</device>
    </audio>
    <wind/>
    <spherical_coordinates>
      <surface_model>EARTH_WGS84</surface_model>
      <latitude_deg>0</latitude_deg>
      <longitude_deg>0</longitude_deg>
      <elevation>0</elevation>
      <heading_deg>0</heading_deg>
    </spherical_coordinates>
    <model name='conveyor_belt'>
      <model name='conveyorbelt_fixed'>
        <static>1</static>
        <link name='belt_visual'>
          <visual name='visual'>
            <geometry>
              <mesh>
                <scale>1 1 1</scale>
                <uri>model://new_conveyor_belt/meshes/new_belt_angled.dae</uri>
              </mesh>
            </geometry>
          </visual>
          <collision name='collision'>
            <geometry>
              <mesh>
                <scale>1 1 1</scale>
                <uri>model://new_conveyor_belt/meshes/new_belt_angled.dae</uri>
              </mesh>
            </geometry>
            <max_contacts>10</max_contacts>
            <surface>
              <contact>
                <ode/>
              </contact>
              <bounce/>
              <friction>
                <torsional>
                  <ode/>
                </torsional>
                <ode/>
              </friction>
            </surface>
            <origin xyz='0.0 0.0 0' rpy='0.0 0.0 0.0'/>
          </collision>
          <self_collide>0</self_collide>
          <enable_wind>0</enable_wind>
          <kinematic>0</kinematic>
        </link>
      </model>
      <model name='conveyorbelt_moving'>
        <allow_auto_disable>0</allow_auto_disable>
        <static>0</static>
        <pose>0 0 0.741 0 -0 0</pose>
        <link name='belt_moving'>
          <inertial>
            <mass>100</mass>
            <inertia>
              <ixx>0</ixx>
              <ixy>0</ixy>
              <ixz>0</ixz>
              <iyy>0</iyy>
              <iyz>0</iyz>
              <izz>0</izz>
            </inertia>
            <pose>0 0 0 0 -0 0</pose>
          </inertial>
          <collision name='belt_collision'>
            <geometry>
              <box>
                <size>0.4 3.2 1e-05</size>
              </box>
            </geometry>
            <surface>
              <friction>
                <ode>
                  <mu>100</mu>
                  <mu2>100</mu2>
                </ode>
                <torsional>
                  <coefficient>1000</coefficient>
                  <patch_radius>0.1</patch_radius>
                  <ode/>
                </torsional>
              </friction>
              <contact>
                <ode/>
              </contact>
              <bounce/>
            </surface>
            <max_contacts>10</max_contacts>
          </collision>
          <self_collide>0</self_collide>
          <enable_wind>0</enable_wind>
          <kinematic>0</kinematic>
        </link>
      </model>
      <joint name='belt_joint' type='prismatic'>
        <parent>conveyorbelt_fixed::belt_visual</parent>
        <child>conveyorbelt_moving::belt_moving</child>
        <axis>
          <xyz expressed_in='__model__'>0 1 0</xyz>
          <limit>
            <lower>0</lower>
            <upper>0.01</upper>
          </limit>
          <dynamics>
            <spring_reference>0</spring_reference>
            <spring_stiffness>0</spring_stiffness>
          </dynamics>
        </axis>
      </joint>
      <plugin name='ros2_conveyorbelt_plugin' filename='libros2_conveyorbelt_plugin.so'>
        <ros>
          <namespace>conveyor_belt_1</namespace>
        </ros>
        <max_velocity>10.0</max_velocity>
        <publish_rate>1000</publish_rate>
      </plugin>
      <pose>0 0 0 0 -0 0</pose>
    </model>
    <state world_name='default'>
      <sim_time>7588 449000000</sim_time>
      <real_time>6021 557997758</real_time>
      <wall_time>1732079740 300068751</wall_time>
      <iterations>5901120</iterations>
      <model name='conveyor_belt'>
        <pose>0 0 0 0 -0 0</pose>
        <scale>1 1 1</scale>
        <model name='conveyorbelt_fixed'>
          <pose>0 0 0 0 -0 0</pose>
          <scale>1 1 1</scale>
          <link name='belt_visual'>
            <pose>0 0 0 0 -0 0</pose>
            <velocity>0 0 0 0 -0 0</velocity>
            <acceleration>0 0 0 0 -0 0</acceleration>
            <wrench>0 0 0 0 -0 0</wrench>
          </link>
        </model>
        <model name='conveyorbelt_moving'>
          <pose>0 0 0.741 0 -0 0</pose>
          <scale>1 1 1</scale>
          <link name='belt_moving'>
            <pose>-0 0.006397 0.741 0 -0 0</pose>
            <velocity>0 -0 0 0 -0 0</velocity>
            <acceleration>0 -1.7e-05 0 0 -0 0</acceleration>
            <wrench>6e-06 -0.001728 4.6e-05 0 -0 0</wrench>
          </link>
        </model>
      </model>
      <model name='ground_plane'>
        <pose>0 0 0 0 -0 0</pose>
        <scale>1 1 1</scale>
        <link name='link'>
          <pose>0 0 0 0 -0 0</pose>
          <velocity>0 0 0 0 -0 0</velocity>
          <acceleration>0 0 0 0 -0 0</acceleration>
          <wrench>0 0 0 0 -0 0</wrench>
        </link>
      </model>
      <light name='sun'>
        <pose>0 0 10 0 -0 0</pose>
      </light>
    </state>
    <gui fullscreen='0'>
      <camera name='user_camera'>
        <pose>-4.2238 -4.44626 2.94593 0 0.267643 0.75219</pose>
        <view_controller>orbit</view_controller>
        <projection_type>perspective</projection_type>
      </camera>
    </gui>
    <plugin name="gazebo_ros_state" filename="libgazebo_ros_state.so">
      <ros>
        <namespace>/gazebo</namespace>
      </ros>
      <update_rate>1.0</update_rate>
    </plugin>
  </world>
</sdf>
